Workbook

Sheet 935
A1: 2000單內排名 | B1: 單字 | C1: KK音標 | D1: 中譯 | E1: 例句 | F1: 翻譯 | G1: 出現次數（歷年加總） | H1: 出現年份數 | I1: 出現年份（民國） | J1: 佔總詞頻% | K1: 累積詞頻% | L1: CEFR難度 | M1: 2000單級別 | N1: 中譯 | O1: 主題分類 | P1: 核心300 | Q1: 鞏固450
A2: 1 | B2: person | C2: =IFERROR(_xlfn.XLOOKUP(B2,'2000'!A:A,'2000'!B:B),"") -> ˈpɝsn | D2: (n.) 人 | E2: He is a very nice person. | F2: 他是個很客氣的人。 | G2: 188 | H2: 10 | I2: 105、106、107、108、109、110、111、112、113、114 | J2: 1.314 | K2: 1.31 | L2: A2 | M2: 1200單 | N2: (n.) 人 | O2: People | P2: ✓
A3: 2 | B3: about | C3: =IFERROR(_xlfn.XLOOKUP(B3,'2000'!A:A,'2000'!B:B),"") -> əˈbaʊt | D3: (prep.) 有關 | E3: This book is about history. | F3: 這本書是關於歷史的。 | G3: 177 | H3: 10 | I3: 105、106、107、108、109、110、111、112、113、114 | J3: 1.237 | K3: 2.55 | L3: 未分類 | M3: 1200單 | N3: (prep.) 有關 | O3: Prepositions | P3: ✓
A4: 3 | B4: from | C4: =IFERROR(_xlfn.XLOOKUP(B4,'2000'!A:A,'2000'!B:B),"") -> frʌm | D4: (prep.) 從… | E4: She is from Canada. | F4: 她來自加拿大。 | G4: 148 | H4: 10 | I4: 105、106、107、108、109、110、111、112、113、114 | J4: 1.034 | K4: 3.59 | L4: 未分類 | M4: 1200單 | N4: (prep.) 從… | O4: Prepositions | P4: ✓
A5: 4 | B5: with | C5: =IFERROR(_xlfn.XLOOKUP(B5,'2000'!A:A,'2000'!B:B),"") -> wɪð | D5: (prep.) 有；用 | E5: She walked into the room with a smile. | F5: 她帶著微笑走進房間。 | G5: 142 | H5: 10 | I5: 105、106、107、108、109、110、111、112、113、114 | J5: 0.992 | K5: 4.58 | L5: 未分類 | M5: 1200單 | N5: (prep.) 有；用 | O5: Prepositions | P5: ✓
A6: 5 | B6: good | C6: =IFERROR(_xlfn.XLOOKUP(B6,'2000'!A:A,'2000'!B:B),"") -> ɡʊd | D6: (adj.) 好的 | E6: This restaurant serves good food. | F6: 這家餐廳的食物很好吃。 | G6: 135 | H6: 10 | I6: 105、106、107、108、109、110、111、112、113、114 | J6: 0.944 | K6: 5.52 | L6: A1 | M6: 1200單 | N6: (adj.) 好的 | O6: Personal characteristics | P6: ✓
A7: 6 | B7: get | C7: =IFERROR(_xlfn.XLOOKUP(B7,'2000'!A:A,'2000'!B:B),"") -> ɡɛt | D7: (v.) 得到 | E7: I need to get some groceries from the store. | F7: 我需要從商店買些雜貨。 | G7: 131 | H7: 10 | I7: 105、106、107、108、109、110、111、112、113、114 | J7: 0.916 | K7: 6.44 | L7: 未分類 | M7: 1200單 | N7: (v.) 得到 | O7: Other verbs | P7: ✓
A8: 7 | B8: time | C8: =IFERROR(_xlfn.XLOOKUP(B8,'2000'!A:A,'2000'!B:B),"") -> taɪm | D8: (n.) 時間 | E8: Time flies when you’re having fun. | F8: 快樂的時光總是飛逝。 | G8: 101 | H8: 10 | I8: 105、106、107、108、109、110、111、112、113、114 | J8: 0.706 | K8: 7.14 | L8: A1 | M8: 1200單 | N8: (n.) 時間 | O8: Time | P8: ✓
A9: 8 | B9: city | C9: =IFERROR(_xlfn.XLOOKUP(B9,'2000'!A:A,'2000'!B:B),"") -> ˈsɪtɪ | D9: (n.) 城市 | E9: New York is a bustling city. | F9: 紐約是一個繁忙的城市。 | G9: 97 | H9: 9 | I9: 105、106、107、108、109、110、112、113、114 | J9: 0.678 | K9: 7.82 | L9: A1 | M9: 1200單 | N9: (n.) 城市 | O9: Places-locations | P9: ✓
A10: 9 | B10: think | C10: =IFERROR(_xlfn.XLOOKUP(B10,'2000'!A:A,'2000'!B:B),"") -> θɪŋk | D10: (v.) 想 | E10: I think it’s going to rain today. | F10: 我認為今天會下雨。 | G10: 94 | H10: 10 | I10: 105、106、107、108、109、110、111、112、113、114 | J10: 0.657 | K10: 8.48 | L10: 未分類 | M10: 800單 | N10: (v.) 認為；思考 | O10: Other nouns | P10: ✓
A11: 10 | B11: know | C11: =IFERROR(_xlfn.XLOOKUP(B11,'2000'!A:A,'2000'!B:B),"") -> no | D11: (v.) 知道 | E11: Do you know where the nearest gas station is? | F11: 你知道最近的加油站在哪裡嗎？ | G11: 84 | H11: 10 | I11: 105、106、107、108、109、110、111、112、113、114 | J11: 0.587 | K11: 9.06 | L11: A1 | M11: 1200單 | N11: (v.) 知道 | O11: Other verbs | P11: ✓
A12: 11 | B12: work | C12: =IFERROR(_xlfn.XLOOKUP(B12,'2000'!A:A,'2000'!B:B),"") -> wɝk | D12: (v.) 工作 | E12: She works at a bank. | F12: 她在銀行工作。 | G12: 83 | H12: 10 | I12: 105、106、107、108、109、110、111、112、113、114 | J12: 0.58 | K12: 9.64 | L12: A1 | M12: 1200單 | N12: (v.) 工作 | O12: Occupations | P12: ✓
A13: 12 | B13: say | C13: =IFERROR(_xlfn.XLOOKUP(B13,'2000'!A:A,'2000'!B:B),"") -> se | D13: (v.) 說 | E13: What did he say to you? | F13: 他對你說了什麼？ | G13: 79 | H13: 10 | I13: 105、106、107、108、109、110、111、112、113、114 | J13: 0.552 | K13: 10.2 | L13: 未分類 | M13: 1200單 | N13: (v.) 說 | O13: School | P13: ✓
... A70: 69 | B70: right | C70: =IFERROR(_xlfn.XLOOKUP(B70,'2000'!A:A,'2000'!B:B),"") -> raɪt | D70: (adj.) 正確的 | E70: You are absolutely right. | F70: 你完全正確。 | G70: 32 | H70: 10 | I70: 105、106、107、108、109、110、111、112、113、114 | J70: 0.224 | K70: 30.44 | L70: A1 | M70: 1200單 | N70: (adj.) 正確的 | O70: Places-locations | P70: ✓
A71: 70 | B71: train | C71: =IFERROR(_xlfn.XLOOKUP(B71,'2000'!A:A,'2000'!B:B),"") -> tren | D71: (n.) 訓練 | E71: She is training for the marathon. | F71: 她正在為馬拉松訓練。 | G71: 32 | H71: 4 | I71: 109110111114 | J71: 0.224 | K71: 30.66 | L71: 未分類 | M71: 1200單 | N71: (n.) 火車；(v.) 訓練 | O71: Transportation | P71: ✓
A72: 71 | B72: well | C72: =IFERROR(_xlfn.XLOOKUP(B72,'2000'!A:A,'2000'!B:B),"") -> wɛl | D72: (adv.) 很好地 | E72: She sings very well. | F72: 她唱得很好。 | G72: 31 | H72: 9 | I72: 105、106、107、108、109、110、111、112、113 | J72: 0.217 | K72: 30.88 | L72: 未分類 | M72: 1200單 | N72: (adv.) 很好地 | O72: Health | P72: ✓
A73: 72 | B73: visit | C73: =IFERROR(_xlfn.XLOOKUP(B73,'2000'!A:A,'2000'!B:B),"") -> ˈvɪzɪt | D73: (v.) 探訪 | E73: We plan to visit our grandparents next week. | F73: 我們計劃下週探望祖父母。 | G73: 31 | H73: 10 | I73: 105、106、107、108、109、110、111、112、113、114 | J73: 0.217 | K73: 31.09 | L73: A2 | M73: 1200單 | N73: (v.) 探訪 | O73: Other verbs | P73: ✓
A74: 73 | B74: bring | C74: =IFERROR(_xlfn.XLOOKUP(B74,'2000'!A:A,'2000'!B:B),"") -> brɪŋ | D74: (v.) 帶來 | E74: Bring me that book, please. | F74: 請把那本書拿給我。 | G74: 31 | H74: 8 | I74: 105、106、107、108、109、112、113、114 | J74: 0.217 | K74: 31.31 | L74: A1 | M74: 1200單 | N74: (v.) 帶來 | O74: Other verbs | P74: ✓
A75: 74 | B75: decide | C75: =IFERROR(_xlfn.XLOOKUP(B75,'2000'!A:A,'2000'!B:B),"") -> dɪˈsaɪd | D75: (v.) 決定 | E75: I decided to take a vacation next month. | F75: 我決定下個月休假。 | G75: 31 | H75: 10 | I75: 105、106、107、108、109、110、111、112、113、114 | J75: 0.217 | K75: 31.53 | L75: A2 | M75: 1200單 | N75: (v.) 決定 | O75: Other verbs | P75: ✓
A76: 75 | B76: however | C76: =IFERROR(_xlfn.XLOOKUP(B76,'2000'!A:A,'2000'!B:B),"") -> haʊˈɛvɚ | D76: (adv.) 然而 | E76: However, we still have a lot of work to do. | F76: 然而，我們仍然有很多工作要做。 | G76: 31 | H76: 10 | I76: 105、106、107、108、109、110、111、112、113、114 | J76: 0.217 | K76: 31.74 | L76: A2 | M76: 1200單 | N76: (adv.) 然而 | O76: Conjunctions | P76: ✓
A77: 76 | B77: teacher | C77: =IFERROR(_xlfn.XLOOKUP(B77,'2000'!A:A,'2000'!B:B),"") -> ˈtitʃɚ | D77: (n.) 老師 | E77: My teacher is very kind and patient. | F77: 我的老師非常善良且有耐心。 | G77: 31 | H77: 4 | I77: 107110111113 | J77: 0.217 | K77: 31.96 | L77: A2 | M77: 1200單 | N77: (n.) 老師；教師 | O77: School | P77: ✓
A78: 77 | B78: weekend | C78: =IFERROR(_xlfn.XLOOKUP(B78,'2000'!A:A,'2000'!B:B),"") -> ˈwikˌɛnd | D78: (n.) 週末 | E78: We went hiking last weekend. | F78: 上週末我們去遠足了。 | G78: 31 | H78: 5 | I78: 108110112113114 | J78: 0.217 | K78: 32.18 | L78: A2 | M78: 1200單 | N78: (n.) 週末 | O78: Time | P78: ✓
A79: 78 | B79: popular | C79: =IFERROR(_xlfn.XLOOKUP(B79,'2000'!A:A,'2000'!B:B),"") -> ˈpɑpjʊlɚ | D79: (adj.) 受歡迎的 | E79: This song is very popular among teenagers. | F79: 這首歌在青少年中非常受歡迎。 | G79: 30 | H79: 9 | I79: 105、106、107、108、109、111、112、113、114 | J79: 0.21 | K79: 32.39 | L79: A1 | M79: 1200單 | N79: (adj.) 受歡迎的 | O79: Other adjectives | P79: ✓
A80: 79 | B80: second | C80: =IFERROR(_xlfn.XLOOKUP(B80,'2000'!A:A,'2000'!B:B),"") -> ˈsɛkənd | D80: (adj.) 第二的 | E80: He came in second place in the race. | F80: 他在比賽中獲得第二名。 | G80: 30 | H80: 9 | I80: 105、106、107、108、109、111、112、113、114 | J80: 0.21 | K80: 32.6 | L80: A1 | M80: 1200單 | N80: (adj.) 第二的 | O80: Time | P80: ✓
A81: 80 | B81: water | C81: =IFERROR(_xlfn.XLOOKUP(B81,'2000'!A:A,'2000'!B:B),"") -> ˈwɔtɚ | D81: (n.) 水 | E81: Drink plenty of water every day. | F81: 每天多喝水。 | G81: 30 | H81: 9 | I81: 105、106、107、108、109、110、111、112、114 | J81: 0.21 | K81: 32.81 | L81: A1 | M81: 1200單 | N81: (n.) 水 | O81: Food & drinks | P81: ✓
A82: 81 | B82: likely | C82: =IFERROR(_xlfn.XLOOKUP(B82,'2000'!A:A,'2000'!B:B),"") -> ˈlaɪklɪ | D82: (adv.) 可能 | E82: It’s likely to rain tomorrow. | F82: 明天可能會下雨。 | G82: 30 | H82: 8 | I82: 105、106、107、108、110、111、113、114 | J82: 0.21 | K82: 33.02 | L82: 未分類 | M82: 800單 | N82: (adj.) 可能的 | O82: Other adjectives | P82: ✓
A83: 82 | B83: try | C83: =IFERROR(_xlfn.XLOOKUP(B83,'2000'!A:A,'2000'!B:B),"") -> traɪ | D83: (v.) 試圖 | E83: I’ll try my best to finish the project on time. | F83: 我會盡力按時完成這個項目。 | G83: 30 | H83: 10 | I83: 105、106、107、108、109、110、111、112、113、114 | J83: 0.21 | K83: 33.23 | L83: A1 | M83: 1200單 | N83: (v.) 試圖 | O83: Other verbs | P83: ✓
A84: 83 | B84: news | C84: =IFERROR(_xlfn.XLOOKUP(B84,'2000'!A:A,'2000'!B:B),"") -> njuz | D84: (n.) 新聞 | E84: Did you hear the latest news? | F84: 你聽到最新的新聞了嗎？ | G84: 30 | H84: 8 | I84: 105、106、107、108、109、111、112、114 | J84: 0.21 | K84: 33.65 | L84: A2 | M84: 1200單 | N84: (n.) 新聞 | O84: Other nouns | P84: ✓
A85: 84 | B85: bird | C85: =IFERROR(_xlfn.XLOOKUP(B85,'2000'!A:A,'2000'!B:B),"") -> bɝd | D85: (n.) 鳥 | E85: A bird flew past the window. | F85: 一隻鳥飛過窗戶。 | G85: 29 | H85: 6 | I85: 105、107、108、111、112、114 | J85: 0.203 | K85: 33.85 | L85: A1 | M85: 1200單 | N85: (n.) 鳥 | O85: Animals & insects | P85: ✓
A86: 85 | B86: move | C86: =IFERROR(_xlfn.XLOOKUP(B86,'2000'!A:A,'2000'!B:B),"") -> muv | D86: (v.) 移動 | E86: Please move the chair closer to the table. | F86: 請把椅子移得靠近桌子一點。 | G86: 29 | H86: 10 | I86: 105、106、107、108、109、110、111、112、113、114 | J86: 0.203 | K86: 34.05 | L86: 未分類 | M86: 1200單 | N86: (v.) 移動 | O86: Other verbs | P86: ✓
A87: 86 | B87: save | C87: =IFERROR(_xlfn.XLOOKUP(B87,'2000'!A:A,'2000'!B:B),"") -> sev | D87: (v.) 拯救 | E87: The firefighters saved the family from the fire. | F87: 消防員從火災中救出了那家人。 | G87: 29 | H87: 9 | I87: 105、106、107、108、109、110、112、113、114 | J87: 0.203 | K87: 34.25 | L87: 未分類 | M87: 1200單 | N87: (v.) 拯救 | O87: Other verbs | P87: ✓
A88: 87 | B88: word | C88: =IFERROR(_xlfn.XLOOKUP(B88,'2000'!A:A,'2000'!B:B),"") -> wɝd | D88: (n.) 字 | E88: Can you spell this word correctly? | F88: 你能正確拼寫這個字嗎？ | G88: 29 | H88: 7 | I88: 105、107、109、111、112、113、114 | J88: 0.203 | K88: 34.46 | L88: 未分類 | M88: 1200單 | N88: (n.) 字 | O88: Other nouns | P88: ✓
A89: 88 | B89: plan | C89: =IFERROR(_xlfn.XLOOKUP(B89,'2000'!A:A,'2000'!B:B),"") -> plæn | D89: (n.) 計畫 | E89: We need to make a plan for the project. | F89: 我們需要為這個項目制定一個計劃。 | G89: 29 | H89: 10 | I89: 105、106、107、108、109、110、111、112、113、114 | J89: 0.203 | K89: 34.66 | L89: A2 | M89: 1200單 | N89: (v.) 計劃；規劃 | O89: Other verbs | P89: ✓
A90: 89 | B90: coffee | C90: =IFERROR(_xlfn.XLOOKUP(B90,'2000'!A:A,'2000'!B:B),"") -> ˈkɔfɪ | D90: (n.) 咖啡 | E90: I drink coffee every morning. | F90: 我每天早上喝咖啡。 | G90: 29 | H90: 4 | I90: 105107108111 | J90: 0.203 | K90: 34.86 | L90: 未分類 | M90: 1200單 | N90: (n.) 咖啡 | O90: Food & drinks | P90: ✓
A91: 90 | B91: pay | C91: =IFERROR(_xlfn.XLOOKUP(B91,'2000'!A:A,'2000'!B:B),"") -> pe | D91: (v.) 付款 | E91: I’ll pay for dinner tonight. | F91: 我今晚請客吃飯。 | G91: 29 | H91: 8 | I91: 106、107、108、109、110、111、112、114 | J91: 0.203 | K91: 35.06 | L91: A1 | M91: 1200單 | N91: (v.) 付款 | O91: Money | P91: ✓
A92: 91 | B92: feel | C92: =IFERROR(_xlfn.XLOOKUP(B92,'2000'!A:A,'2000'!B:B),"") -> fil | D92: (v.) 感覺 | E92: I feel happy today. | F92: 我今天感覺很快樂。 | G92: 28 | H92: 9 | I92: 105、106、107、109、110、111、112、113、114 | J92: 0.196 | K92: 35.26 | L92: A1 | M92: 800單 | N92: (v.) 感覺；覺得 | O92: Other nouns | P92: ✓
A93: 92 | B93: report | C93: =IFERROR(_xlfn.XLOOKUP(B93,'2000'!A:A,'2000'!B:B),"") -> rɪˈport | D93: (n.) 報告 | E93: The teacher asked for a written report. | F93: 老師要求一份書面報告。 | G93: 28 | H93: 7 | I93: 105、106、108、110、111、112、113 | J93: 0.196 | K93: 35.46 | L93: A2 | M93: 1200單 | N93: (n.) 報告 | O93: Other nouns | P93: ✓
A94: 93 | B94: experience | C94: =IFERROR(_xlfn.XLOOKUP(B94,'2000'!A:A,'2000'!B:B),"") -> ɪkˈspɪrɪəns | D94: (n.) 經驗 | E94: Traveling gives you valuable life experiences. | F94: 旅行給你寶貴的人生經驗。 | G94: 28 | H94: 8 | I94: 105、106、108、109、110、112、113、114 | J94: 0.196 | K94: 35.65 | L94: A2 | M94: 1200單 | N94: (n.) 經驗 | O94: Other nouns | P94: ✓
A95: 94 | B95: enjoy | C95: =IFERROR(_xlfn.XLOOKUP(B95,'2000'!A:A,'2000'!B:B),"") -> ɪnˈdʒɔɪ | D95: (v.) 享受 | E95: I enjoy listening to music in my free time. | F95: 我喜歡在空閒時間聽音樂。 | G95: 27 | H95: 8 | I95: 105、108、109、110、111、112、113、114 | J95: 0.189 | K95: 36.04 | L95: A2 | M95: 1200單 | N95: (v.) 享受 | O95: Other verbs | P95: ✓
A96: 95 | B96: even | C96: =IFERROR(_xlfn.XLOOKUP(B96,'2000'!A:A,'2000'!B:B),"") -> ˈivən | D96: (adv.) 甚至 | E96: Even the best players can make mistakes. | F96: 即使是最優秀的球員也會犯錯。 | G96: 27 | H96: 9 | I96: 105、106、107、108、109、110、111、112、113 | J96: 0.189 | K96: 36.22 | L96: 未分類 | M96: 1200單 | N96: (adv.) 甚至 | O96: Other adverbs | P96: ✓
...

Sheet 2000
A1: 英文 | B1: KK音標 | C1: 中譯 | D1: 例句 | E1: 翻譯 | F1: 詞性
A2: able | B2: ˈebl | C2: (adj.) 有能力的 | D2: He is able to solve the problem. | E2: 他有能力解決這個問題。 | F2: 形容詞
A3: about | B3: əˈbaʊt | C3: (prep.) 有關 | D3: This book is about history. | E3: 這本書是關於歷史的。 | F3: 介系詞
A4: above | B4: əˈbʌv | C4: (adv.) 在上方 | D4: The bird flew above the tree. | E4: 鳥兒飛過了樹的上方。 | F4: 副詞
A5: abroad | B5: əˈbrɔd | C5: (adv.) 在國外 | D5: She is studying abroad this year. | E5: 她今年正在國外學習。 | F5: 副詞
A6: absent | B6: ˈæbsənt | C6: (adj.) 缺席的 | D6: John was absent from the meeting yesterday. | E6: 約翰昨天缺席了會議。 | F6: 形容詞
A7: accept | B7: əkˈsɛpt | C7: (v.) 接受 | D7: I can't accept your gift. | E7: 我不能接受你的禮物。 | F7: 動詞
A8: accident | B8: ˈæksədənt | C8: (n.) 意外 | D8: There was a car accident on the highway. | E8: 高速公路上發生了一起車禍。 | F8: 名詞
A9: across | B9: əˈkrɔs | C9: (prep.) 在…對面 | D9: The park is across the street. | E9: 公園在街的對面。 | F9: 介系詞
A10: act | B10: ækt | C10: (n.) 行為 | D10: His act of kindness touched everyone. | E10: 他的善舉感動了每一個人。 | F10: 名詞
A11: action | B11: ˈækʃən | C11: (n.) 活動 | D11: The government took action to improve education. | E11: 政府採取行動改善教育。 | F11: 名詞
A12: active | B12: ˈæktɪv | C12: (adj.) 積極的 | D12: She is an active member of the club. | E12: 她是俱樂部的一名積極成員。 | F12: 形容詞
... A623: fall | B623: fɔl | C623: (v.) 倒下 | D623: The tree fell during the storm. | E623: 樹在暴風雨中倒下了。 | F623: 動詞
A624: FALSE | B624: fɔls | C624: (adj.) 錯的 | D624: The answer is false; you need to correct it. | E624: 答案是錯的，你需要改正它。 | F624: 形容詞
A625: family | B625: ˈfæməlɪ | C625: (n.) 家 | D625: My family is very supportive. | E625: 我的家庭非常支持我。 | F625: 名詞
A626: famous | B626: ˈfeməs | C626: (adj.) 著名的 | D626: This actor is famous all over the world. | E626: 這位演員舉世聞名。 | F626: 形容詞
A627: fan | B627: fæn | C627: (n.) 電扇 | D627: Turn on the fan, it’s getting hot. | E627: 打開電扇，天氣越來越熱了。 | F627: 名詞
A628: fancy | B628: ˈfænsɪ | C628: (n.) 想像力 | D628: Her imagination is full of fancy ideas. | E628: 她的想像力充滿了奇妙的想法。 | F628: 名詞
A629: fantastic | B629: fænˈtæstɪk | C629: (adj.) 極好的 | D629: The movie was absolutely fantastic! | E629: 這部電影簡直棒極了！ | F629: 形容詞
A630: far | B630: fɑr | C630: (adj.) 遠方的 | D630: The beach is far from here. | E630: 海灘離這裡很遠。 | F630: 形容詞
A631: farm | B631: fɑrm | C631: (n.) 農場 | D631: They live on a farm in the countryside. | E631: 他們住在鄉下的農場。 | F631: 名詞
A632: farmer | B632: ˈfɑrmɚ | C632: (n.) 農夫 | D632: The farmer grows wheat and corn. | E632: 這位農夫種植小麥和玉米。 | F632: 名詞
A633: fashion | B633: ˈfæʃən | C633: (n.) 流行 | D633: She always follows the latest fashion trends. | E633: 她總是追隨最新的時尚潮流。 | F633: 名詞
A634: fast | B634: fæst | C634: (adj.) 快的 | D634: The car is very fast. | E634: 這輛車非常快。 | F634: 形容詞
A635: fat | B635: fæt | C635: (adj.) 肥胖的 | D635: Eating too much junk food can make you fat. | E635: 吃太多垃圾食品會讓你變胖。 | F635: 形容詞
A636: father | B636: ˈfɑðɚ | C636: (n.) 父親 | D636: My father is a teacher. | E636: 我父親是一名教師。 | F636: 名詞
... A1510: scare | B1510: skɛr | C1510: (v.) (使)害怕 | D1510: The loud noise scared the children. | E1510: 大聲的噪音嚇到了孩子們。 | F1510: 動詞
A1511: scared | B1511: skɛrd | C1511: (adj.) 驚恐的
A1512: scarf | B1512: skɑrf | C1512: (n.) 圍巾 | D1512: She wore a warm scarf to protect herself from the cold. | E1512: 她圍上一條暖和的圍巾以防寒。 | F1512: 名詞
A1513: scene | B1513: sin | C1513: (n.) 風景 | D1513: The sunset created a beautiful scene. | E1513: 日落創造了一幅美麗的景象。 | F1513: 名詞
A1514: scenery | B1514: ˈsinərɪ | C1514: (n.) 景色 | D1514: The mountain scenery was breathtaking. | E1514: 山區的景色令人驚嘆。 | F1514: 名詞
A1515: school | B1515: skul | C1515: (n.) 學校 | D1515: She goes to school every day. | E1515: 她每天去上學。 | F1515: 名詞
A1516: science | B1516: ˈsaɪəns | C1516: (n.) 科學 | D1516: Science helps us understand the world. | E1516: 科學幫助我們了解世界。 | F1516: 名詞
A1517: scientist | B1517: ˈsaɪəntɪst | C1517: (n.) 科學家 | D1517: The scientist conducted an experiment in the lab. | E1517: 科學家在實驗室進行了一項實驗。 | F1517: 名詞
A1518: scooter | B1518: ˈskutɚ | C1518: (n.) 摩托車 | D1518: He rides a scooter to work every day. | E1518: 他每天騎摩托車上班。 | F1518: 名詞
A1519: score | B1519: skɔr | C1519: (n.) 得分 | D1519: The team scored three goals in the match. | E1519: 球隊在比賽中得了三分。 | F1519: 名詞
A1520: screen | B1520: skrin | C1520: (n.) 螢幕 | D1520: The movie was shown on a large screen. | E1520: 電影在大螢幕上放映。 | F1520: 名詞
A1521: sculpture | B1521: ˈskʌlptʃɚ | C1521: n. 雕塑 | D1521: The artist created a beautiful sculpture. | E1521: 藝術家創作了一件美麗的雕塑。 | F1521: 名詞
A1522: sea | B1522: si | C1522: (n.) 海 | D1522: The sea looks calm today. | E1522: 今天海面看起來很平靜。 | F1522: 名詞
A1523: seafood | B1523: ˈsiˌfud | C1523: (n.) 海鮮 | D1523: I love eating seafood at the restaurant. | E1523: 我喜歡在餐廳吃海鮮。 | F1523: 名詞
...
